<?xml version="1.0" ?>
<!-- =================================================================================== -->
<!-- |    This document was autogenerated by xacro from urdf/robot.urdf.xacro          | -->
<!-- |    EDITING THIS FILE BY HAND IS NOT RECOMMENDED                                 | -->
<!-- =================================================================================== -->
<robot name="ur10" xmlns:controller="http://playerstage.sourceforge.net/gazebo/xmlschema/#controller" xmlns:interface="http://playerstage.sourceforge.net/gazebo/xmlschema/#interface" xmlns:sensor="http://playerstage.sourceforge.net/gazebo/xmlschema/#sensor" xmlns:xacro="http://ros.org/wiki/xacro">
  <gazebo>
    <controller:gazebo_ros_controller_manager name="gazebo_ros_controller_manager" plugin="libgazebo_ros_controller_manager.so">
      <alwaysOn>true</alwaysOn>
      <updateRate>1000.0</updateRate>
      <interface:audio name="gazebo_ros_controller_manager_dummy_iface"/>
    </controller:gazebo_ros_controller_manager>
    <controller:gazebo_ros_power_monitor name="gazebo_ros_power_monitor_controller" plugin="libgazebo_ros_power_monitor.so">
      <alwaysOn>true</alwaysOn>
      <updateRate>1.0</updateRate>
      <timeout>5</timeout>
      <interface:audio name="power_monitor_dummy_interface"/>
      <powerStateTopic>power_state</powerStateTopic>
      <powerStateRate>10.0</powerStateRate>
      <fullChargeCapacity>87.78</fullChargeCapacity>
      <dischargeRate>-474</dischargeRate>
      <chargeRate>525</chargeRate>
      <dischargeVoltage>15.52</dischargeVoltage>
      <chargeVoltage>16.41</chargeVoltage>
    </controller:gazebo_ros_power_monitor>
  </gazebo>
  <link name="base_link">
    <visual>
      <geometry>
        <mesh filename="package://ur10_description/meshes/Base.dae" scale="0.001 0.001 0.001"/>
      </geometry>
      <origin rpy="1.570796325 0.0 0.0" xyz="0.0 0.0 0.0"/>
    </visual>
    <inertial>
      <mass value="4.0"/>
      <inertia ixx="1.0" ixy="0.0" ixz="0.0" iyy="1.0" iyz="0.0" izz="1.0"/>
    </inertial>
  </link>
  <joint name="cart_base_joint" type="fixed">
    <parent link="base_link"/>
    <child link="cart_base_link"/>
    <origin rpy="0.0 0.0 0.0" xyz="0.08 -0.12 -0.915"/>
  </joint>
  <link name="cart_base_link">
    <visual>
      <!--
      <geometry>
          <box size="1.22 0.62 0.915" />
      </geometry>
      -->
      <geometry>
        <mesh filename="package://ur10_description/meshes/cube.dae" scale="1.22 0.62 0.915"/>
      </geometry>
      <origin rpy="0.0 0.0 0.0" xyz="-0.61 0.31 0.458"/>
      <material name="grey">
        <color rgba="0.3 0.3 0.3 1"/>
      </material>
    </visual>
    <collision>
      <geometry>
        <box size="1.22 0.62 0.915"/>
      </geometry>
      <origin rpy="0.0 0.0 0.0" xyz="-0.61 0.31 -0.458"/>
    </collision>
    <inertial>
      <mass value="100"/>
      <inertia ixx="1.0" ixy="0.0" ixz="0.0" iyy="1.0" iyz="0.0" izz="1.0"/>
      <origin rpy="0.0 0.0 0.0" xyz="-0.61 0.31 -0.458"/>
    </inertial>
  </link>
  <joint name="shoulder_pan_joint" type="revolute">
    <parent link="base_link"/>
    <child link="shoulder_link"/>
    <origin rpy="0.0 0.0 0.0" xyz="0.0 0.0 0.1273"/>
    <axis xyz="0.0 0.0 1.0"/>
    <limit effort="10.0" lower="-6.2831853" upper="6.2831853" velocity="3.14159265"/>
    <dynamics damping="10" friction="0.1"/>
  </joint>
  <link name="shoulder_link">
    <visual>
      <geometry>
        <mesh filename="package://ur10_description/meshes/Shoulder.dae" scale="0.001 0.001 0.001"/>
      </geometry>
      <origin rpy="1.570796325 0.0 0.0" xyz="0.0 0.0 -0.127"/>
    </visual>
    <collision>
      <geometry>
        <cylinder length="0.215" radius="0.075"/>
      </geometry>
      <origin rpy="0.0 0.0 0.0" xyz="0.0 0.0 -0.0198"/>
    </collision>
    <inertial>
      <mass value="7.778"/>
      <inertia ixx="1.0" ixy="0.0" ixz="0.0" iyy="1.0" iyz="0.0" izz="1.0"/>
      <origin rpy="0.0 0.0 0.0" xyz="0.00008 0.00244 -0.037"/>
    </inertial>
  </link>
  <joint name="shoulder_lift_joint" type="revolute">
    <parent link="shoulder_link"/>
    <child link="upper_arm_link"/>
    <origin rpy="0.0 1.570796325 0.0" xyz="0.0 0.220941 0.0"/>
    <axis xyz="0.0 1.0 0.0"/>
    <limit effort="10.0" lower="-6.2831853" upper="6.2831853" velocity="3.14159265"/>
    <dynamics damping="10" friction="0.1"/>
  </joint>
  <link name="upper_arm_link">
    <visual>
      <geometry>
        <mesh filename="package://ur10_description/meshes/UpperArm.dae" scale="0.001 0.001 0.001"/>
      </geometry>
      <origin rpy="1.570796325 -0.0 0.0" xyz="0.0 -0.221 -0.127"/>
    </visual>
    <inertial>
      <mass value="12.93"/>
      <inertia ixx="1.0" ixy="0.0" ixz="0.0" iyy="1.0" iyz="0.0" izz="1.0"/>
      <origin rpy="0.0 0.0 0.0" xyz="0.00008 0.00244   0.38757"/>
    </inertial>
  </link>
  <joint name="upper_shoulder_joint" type="fixed">
    <parent link="upper_arm_link"/>
    <child link="upper_shoulder_link"/>
    <origin rpy="-1.570796325 3.14159265 0.0" xyz="0.0 -0.046 0.0"/>
  </joint>
  <link name="upper_shoulder_link">
    <collision>
      <geometry>
        <cylinder length="0.175" radius="0.075"/>
      </geometry>
      <origin rpy="0.0 0.0 0.0" xyz="0.0 0.0 0.0025"/>
    </collision>
    <inertial>
      <mass value="0"/>
      <inertia ixx="1.0" ixy="0.0" ixz="0.0" iyy="1.0" iyz="0.0" izz="1.0"/>
      <origin rpy="0.0 0.0 0.0" xyz="0.0 0.0 0.0"/>
    </inertial>
  </link>
  <joint name="upper_arm_middle_joint" type="fixed">
    <parent link="upper_arm_link"/>
    <child link="upper_arm_middle_link"/>
    <origin rpy="-1.570796325 3.14159265 0.0" xyz="0.0 -0.046 0.32"/>
  </joint>
  <link name="upper_arm_middle_link">
    <collision>
      <geometry>
        <cylinder length="0.45" radius="0.0525"/>
      </geometry>
      <origin rpy="1.570796325 0.0 0.0" xyz="0.0 0.0 0.0"/>
    </collision>
    <inertial>
      <mass value="0"/>
      <inertia ixx="1.0" ixy="0.0" ixz="0.0" iyy="1.0" iyz="0.0" izz="1.0"/>
      <origin rpy="0.0 0.0 0.0" xyz="0.0 0.0 0.0"/>
    </inertial>
  </link>
  <joint name="elbow_joint" type="revolute">
    <parent link="upper_arm_link"/>
    <child link="forearm_link"/>
    <origin rpy="0.0 0.0 0.0" xyz="0.0 -0.1719 0.612"/>
    <axis xyz="0.0 1.0 0.0"/>
    <limit effort="10.0" lower="-6.2831853" upper="6.2831853" velocity="3.14159265"/>
    <dynamics damping="10" friction="0.1"/>
  </joint>
  <link name="forearm_link">
    <visual>
      <geometry>
        <mesh filename="package://ur10_description/meshes/Forearm.dae" scale="0.001 0.001 0.001"/>
      </geometry>
      <origin rpy="1.570796325 0.0 0.0" xyz="0.0 -0.049 -0.739"/>
    </visual>
    <collision>
      <geometry>
        <cylinder length="0.26" radius="0.06"/>
      </geometry>
      <origin rpy="1.570796325 0.0 0.0" xyz="0.0 0.065 0.0"/>
    </collision>
    <inertial>
      <mass value="3.87"/>
      <origin rpy="0.0 0.0 0.0" xyz="0.0 0.0265 0.11993"/>
      <inertia ixx="1.0" ixy="0.0" ixz="0.0" iyy="1.0" iyz="0.0" izz="1.0"/>
    </inertial>
  </link>
  <joint name="forearm_middle_joint" type="fixed">
    <parent link="forearm_link"/>
    <child link="forearm_middle_link"/>
    <origin rpy="0.0 0.0 0.0" xyz="0.0 0.0 0.295"/>
  </joint>
  <link name="forearm_middle_link">
    <collision>
      <geometry>
        <cylinder length="0.45" radius="0.043"/>
      </geometry>
      <origin rpy="0.0 0.0 0.0" xyz="0.0 0.0 0.0"/>
    </collision>
    <inertial>
      <mass value="0"/>
      <inertia ixx="1.0" ixy="0.0" ixz="0.0" iyy="1.0" iyz="0.0" izz="1.0"/>
      <origin rpy="0.0 0.0 0.0" xyz="0.0 0.0 0.0"/>
    </inertial>
  </link>
  <joint name="wrist_1_joint" type="revolute">
    <parent link="forearm_link"/>
    <child link="wrist_1_link"/>
    <origin rpy="0.0 1.570796325 0.0" xyz="0.0 0.0 0.5723"/>
    <axis xyz="0.0 1.0 0.0"/>
    <limit effort="10.0" lower="-6.2831853" upper="6.2831853" velocity="3.14159265"/>
    <dynamics damping="10" friction="0.1"/>
  </joint>
  <link name="wrist_1_link">
    <visual>
      <geometry>
        <mesh filename="package://ur10_description/meshes/Wrist1.dae" scale="0.001 0.001 0.001"/>
      </geometry>
      <origin rpy="1.570796325 0.0 0.0" xyz="0.0 -0.049 -1.312"/>
    </visual>
    <collision>
      <geometry>
        <cylinder length="0.123" radius="0.045"/>
      </geometry>
      <origin rpy="-1.570796325 0.0 0.0" xyz="0.0 0.0045 0.0"/>
    </collision>
    <inertial>
      <mass value="1.96"/>
      <origin rpy="0.0 0.0 0.0" xyz="0.0 0.110949 0.01634"/>
      <inertia ixx="1.0" ixy="0.0" ixz="0.0" iyy="1.0" iyz="0.0" izz="1.0"/>
    </inertial>
  </link>
  <joint name="wrist_2_joint" type="revolute">
    <parent link="wrist_1_link"/>
    <child link="wrist_2_link"/>
    <origin rpy="0.0 0.0 0.0" xyz="0.0 0.1149 0.0"/>
    <axis xyz="0.0 0.0 1.0"/>
    <limit effort="10.0" lower="-6.2831853" upper="6.2831853" velocity="3.14159265"/>
    <dynamics damping="10" friction="0.1"/>
  </joint>
  <link name="wrist_2_link">
    <visual>
      <geometry>
        <mesh filename="package://ur10_description/meshes/Wrist2.dae" scale="0.001 0.001 0.001"/>
      </geometry>
      <origin rpy="1.570796325 0.0 0.0" xyz="0.0 -0.164 -1.312"/>
    </visual>
    <collision>
      <geometry>
        <cylinder length="0.123" radius="0.045"/>
      </geometry>
      <origin rpy="0.0 0.0 0.0" xyz="0.0 0.0 0.0045"/>
    </collision>
    <inertial>
      <mass value="1.96"/>
      <origin rpy="0.0 0.0 0.0" xyz="0.0 0.0018 0.11099"/>
      <inertia ixx="1.0" ixy="0.0" ixz="0.0" iyy="1.0" iyz="0.0" izz="1.0"/>
    </inertial>
  </link>
  <joint name="wrist_3_joint" type="revolute">
    <parent link="wrist_2_link"/>
    <child link="wrist_3_link"/>
    <origin rpy="0.0 0.0 0.0" xyz="0.0 0.0 0.1157"/>
    <axis xyz="0.0 1.0 0.0"/>
    <limit effort="10.0" lower="-6.2831853" upper="6.2831853" velocity="3.14159265"/>
    <dynamics damping="10" friction="0.1"/>
  </joint>
  <link name="wrist_3_link">
    <visual>
      <geometry>
        <mesh filename="package://ur10_description/meshes/Wrist3.dae" scale="0.001 0.001 0.001"/>
      </geometry>
      <origin rpy="1.570796325 0.0 0.0" xyz="0.0 -0.164 -1.427"/>
    </visual>
    <collision>
      <geometry>
        <cylinder length="0.148" radius="0.045"/>
      </geometry>
      <origin rpy="-1.570796325 0.0 0.0" xyz="0.0 0.017 0.0"/>
    </collision>
    <inertial>
      <mass value="0.202"/>
      <origin rpy="0.0 0.0 0.0" xyz="0.0 0.001159 0.0"/>
      <inertia ixx="1.0" ixy="0.0" ixz="0.0" iyy="1.0" iyz="0.0" izz="1.0"/>
    </inertial>
  </link>
  <joint name="ee_fixed_joint" type="fixed">
    <parent link="wrist_3_link"/>
    <child link="ee_link"/>
    <origin rpy="0.0 0.0 1.570796325" xyz="0.0 0.0922 0.0"/>
  </joint>
  <link name="ee_link"/>
  <transmission name="shoulder_pan_trans" type="pr2_mechanism_model/SimpleTransmission">
    <actuator name="shoulder_pan_motor"/>
    <joint name="shoulder_pan_joint"/>
    <mechanicalReduction>1</mechanicalReduction>
  </transmission>
  <transmission name="shoulder_lift_trans" type="pr2_mechanism_model/SimpleTransmission">
    <actuator name="shoulder_lift_motor"/>
    <joint name="shoulder_lift_joint"/>
    <mechanicalReduction>1</mechanicalReduction>
  </transmission>
  <transmission name="elbow_trans" type="pr2_mechanism_model/SimpleTransmission">
    <actuator name="elbow_motor"/>
    <joint name="elbow_joint"/>
    <mechanicalReduction>1</mechanicalReduction>
  </transmission>
  <transmission name="wrist_1_trans" type="pr2_mechanism_model/SimpleTransmission">
    <actuator name="wrist_1_motor"/>
    <joint name="wrist_1_joint"/>
    <mechanicalReduction>1</mechanicalReduction>
  </transmission>
  <transmission name="wrist_2_trans" type="pr2_mechanism_model/SimpleTransmission">
    <actuator name="wrist_2_motor"/>
    <joint name="wrist_2_joint"/>
    <mechanicalReduction>1</mechanicalReduction>
  </transmission>
  <transmission name="wrist_3_trans" type="pr2_mechanism_model/SimpleTransmission">
    <actuator name="wrist_3_motor"/>
    <joint name="wrist_3_joint"/>
    <mechanicalReduction>1</mechanicalReduction>
  </transmission>
  <gazebo reference="universal_robot">
    <material>Gazebo/Blue</material>
  </gazebo>
</robot>

